<?xml version="1.0" encoding="utf-8"?>
<!-- This URDF was automatically created by SolidWorks to URDF Exporter! Originally created by Stephen Brawner (brawner@gmail.com) 
     Commit Version: 1.6.0-4-g7f85cfe  Build Version: 1.6.7995.38578
     For more information, please see http://wiki.ros.org/sw_urdf_exporter -->
<robot
  name="car_urdf">
  <link
    name="base_link">
    <inertial>
      <origin
        xyz="-0.00645768872727767 3.74512612866251E-07 0.0351213518570509"
        rpy="0 0 0" />
      <mass
        value="1.02425311665903" />
      <inertia
        ixx="0.00114885526776431"
        ixy="2.22477424151059E-05"
        ixz="-3.85197330179937E-08"
        iyy="0.00140731737401737"
        iyz="-4.58277469124373E-06"
        izz="0.00232634507862739" />
    </inertial>
    <visual>
      <origin
        xyz="0 0 0"
        rpy="0 0 0" />
      <geometry>
        <mesh
          filename="package://car_urdf/meshes/base_link.STL" />
      </geometry>
      <material
        name="">
        <color
          rgba="0.792156862745098 0.819607843137255 0.933333333333333 1" />
      </material>
    </visual>
    <collision>
      <origin
        xyz="0 0 0"
        rpy="0 0 0" />
      <geometry>
        <mesh
          filename="package://car_urdf/meshes/base_link.STL" />
      </geometry>
    </collision>
  </link>
  <link
    name="back_left_wheel">
    <inertial>
      <origin
        xyz="0 -4.16333634234434E-17 -0.0125482409238937"
        rpy="0 0 0" />
      <mass
        value="0.0578292592084442" />
      <inertia
        ixx="2.66275510837215E-05"
        ixy="-2.10249235348185E-21"
        ixz="9.82495083339318E-21"
        iyy="2.66275510837215E-05"
        iyz="7.45810730015738E-20"
        izz="4.68259214243964E-05" />
    </inertial>
    <visual>
      <origin
        xyz="0 0 0"
        rpy="0 0 0" />
      <geometry>
        <mesh
          filename="package://car_urdf/meshes/back_left_wheel.STL" />
      </geometry>
      <material
        name="">
        <color
          rgba="0.792156862745098 0.819607843137255 0.933333333333333 1" />
      </material>
    </visual>
    <collision>
      <origin
        xyz="0 0 0"
        rpy="0 0 0" />
      <geometry>
        <mesh
          filename="package://car_urdf/meshes/back_left_wheel.STL" />
      </geometry>
    </collision>
  </link>
  <joint
    name="back_left_wheel_joint"
    type="continuous">
    <origin
      xyz="-0.09 0.116 -0.01"
      rpy="-1.5708 0 0" />
    <parent
      link="base_link" />
    <child
      link="back_left_wheel" />
    <axis
      xyz="0 0 1" />
    <limit
      effort="10"
      velocity="10" />
    <dynamics
      damping="0.1"
      friction="0.1" />
  </joint>
  <link
    name="back_right_wheel">
    <inertial>
      <origin
        xyz="2.77555756156289E-17 6.93889390390723E-17 -0.0125482409238937"
        rpy="0 0 0" />
      <mass
        value="0.0578292592084443" />
      <inertia
        ixx="2.66275510837215E-05"
        ixy="-6.28509923993659E-22"
        ixz="-8.78162986040991E-21"
        iyy="2.66275510837215E-05"
        iyz="-7.06301331072774E-20"
        izz="4.68259214243965E-05" />
    </inertial>
    <visual>
      <origin
        xyz="0 0 0"
        rpy="0 0 0" />
      <geometry>
        <mesh
          filename="package://car_urdf/meshes/back_right_wheel.STL" />
      </geometry>
      <material
        name="">
        <color
          rgba="0.792156862745098 0.819607843137255 0.933333333333333 1" />
      </material>
    </visual>
    <collision>
      <origin
        xyz="0 0 0"
        rpy="0 0 0" />
      <geometry>
        <mesh
          filename="package://car_urdf/meshes/back_right_wheel.STL" />
      </geometry>
    </collision>
  </link>
  <joint
    name="back_right_wheel_joint"
    type="continuous">
    <origin
      xyz="-0.09 -0.116 -0.01"
      rpy="1.5708 0 0" />
    <parent
      link="base_link" />
    <child
      link="back_right_wheel" />
    <axis
      xyz="0 0 -1" />
    <limit
      effort="10"
      velocity="10" />
    <dynamics
      damping="0.1"
      friction="0.1" />
  </joint>
  <link
    name="turn_left_wheel">
    <inertial>
      <origin
        xyz="6.93889390390723E-18 -0.00113877791740061 0"
        rpy="0 0 0" />
      <mass
        value="0.00426270283294646" />
      <inertia
        ixx="2.44795132666107E-07"
        ixy="1.3400868606092E-22"
        ixz="2.18104263075495E-23"
        iyy="2.69880515935288E-07"
        iyz="-2.42131476952577E-22"
        izz="2.44795132666107E-07" />
    </inertial>
    <visual>
      <origin
        xyz="0 0 0"
        rpy="0 0 0" />
      <geometry>
        <mesh
          filename="package://car_urdf/meshes/turn_left_wheel.STL" />
      </geometry>
      <material
        name="">
        <color
          rgba="0.792156862745098 0.819607843137255 0.933333333333333 1" />
      </material>
    </visual>
    <collision>
      <origin
        xyz="0 0 0"
        rpy="0 0 0" />
      <geometry>
        <mesh
          filename="package://car_urdf/meshes/turn_left_wheel.STL" />
      </geometry>
    </collision>
  </link>
  <joint
    name="turn_left_wheel_joint"
    type="revolute">
    <origin
      xyz="0.080107 0.0945 -0.013"
      rpy="0 0 0" />
    <parent
      link="base_link" />
    <child
      link="turn_left_wheel" />
    <axis
      xyz="0 0 1" />
    <limit
      lower="-0.3925"
      upper="0.3925"
      effort="10"
      velocity="10" />
    <dynamics
      damping="0.1"
      friction="0.1" />
  </joint>
  <link
    name="front_left_wheel">
    <inertial>
      <origin
        xyz="1.04083408558608E-16 0.0109517590761063 -8.32667268468867E-17"
        rpy="0 0 0" />
      <mass
        value="0.0578292592084442" />
      <inertia
        ixx="2.66275510837215E-05"
        ixy="8.87627599938019E-20"
        ixz="9.21692029061869E-22"
        iyy="4.68259214243964E-05"
        iyz="-1.44573487488331E-19"
        izz="2.66275510837215E-05" />
    </inertial>
    <visual>
      <origin
        xyz="0 0 0"
        rpy="0 0 0" />
      <geometry>
        <mesh
          filename="package://car_urdf/meshes/front_left_wheel.STL" />
      </geometry>
      <material
        name="">
        <color
          rgba="0.792156862745098 0.819607843137255 0.933333333333333 1" />
      </material>
    </visual>
    <collision>
      <origin
        xyz="0 0 0"
        rpy="0 0 0" />
      <geometry>
        <mesh
          filename="package://car_urdf/meshes/front_left_wheel.STL" />
      </geometry>
    </collision>
  </link>
  <joint
    name="front_left_wheel_joint"
    type="continuous">
    <origin
      xyz="0 0 0"
      rpy="0 0 0" />
    <parent
      link="turn_left_wheel" />
    <child
      link="front_left_wheel" />
    <axis
      xyz="0 1 0" />
    <limit
      effort="10"
      velocity="10" />
    <dynamics
      damping="0.1"
      friction="0.1" />
  </joint>
  <link
    name="turn_right_wheel">
    <inertial>
      <origin
        xyz="4.85722573273506E-17 0.00113877791740072 1.38777878078145E-17"
        rpy="0 0 0" />
      <mass
        value="0.00426270283294647" />
      <inertia
        ixx="2.44795132666107E-07"
        ixy="1.05432241845345E-22"
        ixz="-1.61558713389338E-24"
        iyy="2.69880515935288E-07"
        iyz="-1.82818599944427E-22"
        izz="2.44795132666107E-07" />
    </inertial>
    <visual>
      <origin
        xyz="0 0 0"
        rpy="0 0 0" />
      <geometry>
        <mesh
          filename="package://car_urdf/meshes/turn_right_wheel.STL" />
      </geometry>
      <material
        name="">
        <color
          rgba="0.792156862745098 0.819607843137255 0.933333333333333 1" />
      </material>
    </visual>
    <collision>
      <origin
        xyz="0 0 0"
        rpy="0 0 0" />
      <geometry>
        <mesh
          filename="package://car_urdf/meshes/turn_right_wheel.STL" />
      </geometry>
    </collision>
  </link>
  <joint
    name="turn_right_wheel_joint"
    type="revolute">
    <origin
      xyz="0.080107 -0.0945 -0.013"
      rpy="0 0 0" />
    <parent
      link="base_link" />
    <child
      link="turn_right_wheel" />
    <axis
      xyz="0 0 1" />
    <limit
      lower="-0.3925"
      upper="0.3925"
      effort="10"
      velocity="10" />
    <dynamics
      damping="0.1"
      friction="0.1" />
  </joint>
  <link
    name="front_right_wheel">
    <inertial>
      <origin
        xyz="-1.80411241501588E-16 -0.0109517590761062 1.38777878078145E-16"
        rpy="0 0 0" />
      <mass
        value="0.0578292592084443" />
      <inertia
        ixx="2.66275510837215E-05"
        ixy="7.25787420182212E-20"
        ixz="1.47501403572567E-21"
        iyy="4.68259214243965E-05"
        iyz="-1.37848677754755E-19"
        izz="2.66275510837215E-05" />
    </inertial>
    <visual>
      <origin
        xyz="0 0 0"
        rpy="0 0 0" />
      <geometry>
        <mesh
          filename="package://car_urdf/meshes/front_right_wheel.STL" />
      </geometry>
      <material
        name="">
        <color
          rgba="0.792156862745098 0.819607843137255 0.933333333333333 1" />
      </material>
    </visual>
    <collision>
      <origin
        xyz="0 0 0"
        rpy="0 0 0" />
      <geometry>
        <mesh
          filename="package://car_urdf/meshes/front_right_wheel.STL" />
      </geometry>
    </collision>
  </link>
  <joint
    name="front_right_wheel_joint"
    type="continuous">
    <origin
      xyz="0 0 0"
      rpy="0 0 0" />
    <parent
      link="turn_right_wheel" />
    <child
      link="front_right_wheel" />
    <axis
      xyz="0 1 0" />
    <limit
      effort="10"
      velocity="10" />
    <dynamics
      damping="0.1"
      friction="0.1" />
  </joint>
</robot>